import { ApiError } from './ApiError'
import { makeRequest } from './makeRequest'

describe('makeRequest', () => {
  test.each([
    [
      function (_input: RequestInfo | URL, _init?: RequestInit): Promise<Response> {
        const response = new Response('{"items":[{"key":"value"}]}', {
          status: 200,
          statusText: 'Super duper!',
          headers: {
            'Content-Type': 'application/json',
          },
        })

        return Promise.resolve(response)
      },
      {
        items: [
          {
            key: 'value',
          },
        ],
      },
      {
        status: 200,
        statusText: 'Super duper!',
      },
    ],
    [
      function (_input: RequestInfo | URL, _init?: RequestInit): Promise<Response> {
        const response = new Response('{"items":[{"key":"value"}]}', {
          status: 200,
          statusText: 'Super duper!',
          headers: {
            'Content-Type': 'application/json; charset=utf-8',
          },
        })

        return Promise.resolve(response)
      },
      {
        items: [
          {
            key: 'value',
          },
        ],
      },
      {
        status: 200,
        statusText: 'Super duper!',
      },
    ],
    [
      function (_input: RequestInfo | URL, _init?: RequestInit): Promise<Response> {
        const response = new Response('OK', {
          status: 200,
          statusText: 'Super duper!',
          headers: {
            'Content-Type': 'plain/text',
          },
        })

        return Promise.resolve(response)
      },
      'OK',
      {
        status: 200,
        statusText: 'Super duper!',
      },
    ],
  ])('works for requests that succeed and return a success status', async (fetchMock, expectedData, expectedPartialResponse) => {
    jest.spyOn(global, 'fetch').mockImplementation(fetchMock)

    const { data, response } = await makeRequest('/')

    expect(data).toEqual(expectedData)
    expect(response).toEqual(expect.objectContaining(expectedPartialResponse))
  })

  test.each([
    [
      function (_input: RequestInfo | URL, _init?: RequestInit): Promise<Response> {
        return Promise.reject(new Error('A most terrible error'))
      },
      new Error('A most terrible error'),
    ],
    [
      function (_input: RequestInfo | URL, _init?: RequestInit): Promise<Response> {
        // We specifically want to test this edge case.
        // eslint-disable-next-line prefer-promise-reject-errors
        return Promise.reject('Now thatâ€™s just great')
      },
      new Error('An unknown network error occurred.'),
    ],
  ])('works for requests that fail with a network error', async (fetchMock, expectedError) => {
    jest.spyOn(global, 'fetch').mockImplementation(fetchMock)

    await expect(() => makeRequest('/')).rejects.toThrow(expectedError)
  })

  test.each([
    [
      'minimal error response format',
      function (_input: RequestInfo | URL, _init?: RequestInit): Promise<Response> {
        const response = new Response('{"code":"great_misfortune","details":"A most terrible error"}', {
          status: 400,
          statusText: 'Oh no!',
          headers: {
            'Content-Type': 'application/json',
          },
        })

        return Promise.resolve(response)
      },
      new ApiError({
        code: 'great_misfortune',
        statusCode: 400,
        message: 'A most terrible error',
      }),
    ],
    [
      'complete error response format',
      function (_input: RequestInfo | URL, _init?: RequestInit): Promise<Response> {
        const response = new Response('{"code":"great_misfortune","title":"Validation error","details":"A most terrible error"}', {
          status: 400,
          statusText: 'Oh no!',
          headers: {
            'Content-Type': 'application/json',
          },
        })

        return Promise.resolve(response)
      },
      new ApiError({
        code: 'great_misfortune',
        statusCode: 400,
        title: 'Validation error',
        message: 'A most terrible error',
      }),
    ],
    [
      'complete error response format with causes',
      function (_input: RequestInfo | URL, _init?: RequestInit): Promise<Response> {
        const response = new Response(
          `
            {
              "code": "great_misfortune",
              "title": "Validation error",
              "details": "A most terrible error",
              "causes": [
                {
                  "field": "id",
                  "message": "This field is required."
                }
              ]
            }
          `,
          {
            status: 400,
            statusText: 'Oh no!',
            headers: {
              'Content-Type': 'application/json',
            },
          },
        )

        return Promise.resolve(response)
      },
      new ApiError({
        code: 'great_misfortune',
        statusCode: 400,
        title: 'Validation error',
        message: 'A most terrible error',
        causes: [
          {
            field: 'id',
            message: 'This field is required.',
          },
        ],
      }),
    ],
    [
      'unknown error response format',
      function (_input: RequestInfo | URL, _init?: RequestInit): Promise<Response> {
        const response = new Response('{"items":[]}', {
          status: 400,
          headers: {
            'Content-Type': 'application/json',
          },
        })

        return Promise.resolve(response)
      },
      new ApiError({
        statusCode: 400,
        message: 'An error has occurred while trying to load this data.',
      }),
    ],
    [
      'plain text response',
      function (_input: RequestInfo | URL, _init?: RequestInit): Promise<Response> {
        const response = new Response('Not found!', { status: 404 })

        return Promise.resolve(response)
      },
      new ApiError({
        statusCode: 404,
        message: 'Not found!',
      }),
    ],
  ])('works for requests that succeed but return a failure statuses (%s)', async (title, fetchMock, expectedError) => {
    jest.spyOn(global, 'fetch').mockImplementation(fetchMock)

    const call = () => makeRequest('/')

    // Note: The following assertion will only check if the thrown error is an `ApiError` and if its message is correct. Its further contents **cannot** be checked like this. For this reason, this slightly bit of heretical code below is employed. It will compare the entire error shape with the expected form.
    await expect(call).rejects.toThrowError(expectedError)

    const thrownError = await getThrownApiError(call)
    expect(thrownError.toJSON()).toEqual(expectedError.toJSON())
  })
})

async function getThrownApiError(call: () => Promise<unknown>): Promise<ApiError> {
  let thrownError

  try {
    await call()
  } catch (error) {
    thrownError = error
  }

  return thrownError as ApiError
}
